// Copyright Titanium I.T. LLC.
"use strict";

const assert = require("./assert");

describe("Assert", () => {

	describe("throwsAsync()", () => {

		it("passes if function throws and there's no expectation", async () => {
			await expectPassAsync(async () => {
				await assert.throwsAsync(() => Promise.reject(new Error("any error")));
			});
		});

		it("passes if function throws and error message matches expected string", async () => {
			await expectPassAsync(async () => {
				await assert.throwsAsync(
					() => Promise.reject(new Error("my error")),
					"my error"
				);
			});
		});

		it("passes if function throws and error message matches regex", async () => {
			await expectPassAsync(async () => {
				await assert.throwsAsync(
					() => Promise.reject(new Error("my complicated error message")),
					/complicated/
				);
			});
		});

		it("fails if function doesn't throw", async () => {
			await expectFailAsync(async () => {
				await assert.throwsAsync(() => Promise.resolve());
			}, "Expected exception");
		});

		it("fails if function throws and error message doesn't match expected string", async () => {
			await expectFailAsync(async () => {
				await assert.throwsAsync(
					() => Promise.reject(new Error("my error")),
					"not my error"
				);
			}, "expected 'my error' to equal 'not my error'");
		});

		it("passes if function throws and error message doesn't match regex", async () => {
			await expectFailAsync(async () => {
				await assert.throwsAsync(
					() => Promise.reject(new Error("my complicated error message")),
					/not-found/
				);
			}, "expected 'my complicated error message' to match /not-found/");
		});

	});


	describe("doesNotThrowAsync()", () => {

		it("passes if function does not throw exception", async () => {
			await expectPassAsync(async () => {
				await assert.doesNotThrowAsync(() => Promise.resolve());
			});
		});

		it("fails if function does throw exception", async () => {
			await expectFailAsync(async () => {
				await assert.doesNotThrowAsync(() => Promise.reject(new Error("my error")));
			}, "my error");
		});

	});


	describe("promiseResolvesAsync()", () => {

		it("passes if promise resolves", async () => {
			await expectPassAsync(async () => {
				const promise = new Promise((resolve) => setImmediate(resolve));
				await assert.promiseResolvesAsync(promise);
			});
		});

		it("fails if promise doesn't resolve", async () => {
			await expectFailAsync(async () => {
				const promise = new Promise(() => {});
				await assert.promiseResolvesAsync(promise);
			}, "Expected promise to resolve, but it didn't");
		});

	});


	describe("promiseDoesNotResolveAsync()", () => {

		it("passes if promise doesn't resolve", async () => {
			await expectPassAsync(async () => {
				const promise = new Promise(() => {});
				await assert.promiseDoesNotResolveAsync(promise);
			});
		});

		it("fails if promise does resolve", async () => {
			await expectFailAsync(async () => {
				const promise = new Promise((resolve) => setImmediate(resolve));
				await assert.promiseDoesNotResolveAsync(promise);
			}, "Expected promise to not resolve, but it did");
		});

	});

});

async function expectPassAsync(fnAsync) {
	await fnAsync();
}

async function expectFailAsync(fnAsync, expectedFailureMessage) {
	try {
		await fnAsync();
	}
	catch (err) {
		assert.equal(err.message, expectedFailureMessage);
		return;
	}
	assert.fail("Expected assertion to fail, but it passed");
}